{
  "errors": [
    {
      "test": "microservice_tests.TestMicroservice.test_add_endpoint",
      "traceback": "Traceback (most recent call last):\n  File \"C:\\Users\\DELL\\AppData\\Local\\Programs\\Python\\Python312\\Lib\\unittest\\case.py\", line 58, in testPartExecutor\n    yield\n  File \"C:\\Users\\DELL\\AppData\\Local\\Programs\\Python\\Python312\\Lib\\unittest\\case.py\", line 634, in run\n    self._callTestMethod(testMethod)\n    ^^^^^^^^^^^^^^^^^\n  File \"C:\\Users\\DELL\\AppData\\Local\\Programs\\Python\\Python312\\Lib\\unittest\\case.py\", line 589, in _callTestMethod\n    if method() is not None:\n    ^^^^^^^^^^^^^^^^^\n  File \"c:\\users\\dell\\bits_lab\\devopsassignment\\src\\unittest\\python\\microservice_tests.py\", line 9, in test_add_endpoint\n    response = requests.get('http://127.0.0.1:5000/api/add?num1=3&num2=5')\n    ^^^^^^^^^^^^^^^^^\n  File \"c:\\users\\dell\\bits_lab\\devopsassignment\\.pybuilder\\plugins\\cpython-3.12.2.final.0\\lib\\site-packages\\requests\\api.py\", line 73, in get\n    return request(\"get\", url, params=params, **kwargs)\n      ^^^^^^^^^^^^^^^^^\n  File \"c:\\users\\dell\\bits_lab\\devopsassignment\\.pybuilder\\plugins\\cpython-3.12.2.final.0\\lib\\site-packages\\requests\\api.py\", line 59, in request\n    return session.request(method=method, url=url, **kwargs)\n    ^^^^^^^^^^^^^^^^^\n  File \"c:\\users\\dell\\bits_lab\\devopsassignment\\.pybuilder\\plugins\\cpython-3.12.2.final.0\\lib\\site-packages\\requests\\sessions.py\", line 589, in request\n    resp = self.send(prep, **send_kwargs)\n    ^^^^^^^^^^^^^^^^^\n  File \"c:\\users\\dell\\bits_lab\\devopsassignment\\.pybuilder\\plugins\\cpython-3.12.2.final.0\\lib\\site-packages\\requests\\sessions.py\", line 703, in send\n    r = adapter.send(request, **kwargs)\n    ^^^^^^^^^^^^^^^^^\n  File \"c:\\users\\dell\\bits_lab\\devopsassignment\\.pybuilder\\plugins\\cpython-3.12.2.final.0\\lib\\site-packages\\requests\\adapters.py\", line 519, in send\n    raise ConnectionError(e, request=request)\n    ^^^^^^^^^^^^^^^^^\nrequests.exceptions.ConnectionError: None: Max retries exceeded with url: /api/add?num1=3&num2=5 (Caused by None)\n"
    }
  ],
  "failures": [],
  "tests-run": 1
}